<?xml version="1.0" ?>
<!-- =================================================================================== -->
<!-- |    This document was autogenerated by xacro from sp8.urdf.xacro                 | -->
<!-- |    EDITING THIS FILE BY HAND IS NOT RECOMMENDED                                 | -->
<!-- =================================================================================== -->
<robot name="sp8">
  <!-- Specify some standard inertial calculations https://en.wikipedia.org/wiki/List_of_moments_of_inertia -->
  <!-- These make use of xacro's mathematical functionality -->
  <material name="white">
    <color rgba="1.0 1.0 1.0 0.7"/>
  </material>
  <material name="black">
    <color rgba="0.0 0.0 0.0 1.0"/>
  </material>
  <!-- BASE FOOTPRINT LINK-->
  <link name="base_footprint">
        
    </link>
  <!-- BASE LINK -->
  <joint name="base_link_joint" type="fixed">
    <parent link="base_footprint"/>
    <child link="base_link"/>
    <origin xyz="0.0 0.0 0.052"/>
    <!-- 0.052-->
  </joint>
  <link name="base_link">
    <visual>
      <origin xyz="0.0 0.0 0.036"/>
      <geometry>
        <cylinder length="0.1" radius="0.125"/>
      </geometry>
      <material name="white"/>
    </visual>
    <collision>
      <origin xyz="0.0 0.0 0.036"/>
      <geometry>
        <cylinder length="0.1" radius="0.125"/>
      </geometry>
    </collision>
    <inertial>
      <origin rpy="0.0 0.0 0.0" xyz="0.0 0.0 0.036"/>
      <mass value="3.0"/>
      <inertia ixx="0.01421875" ixy="0.0" ixz="0.0" iyy="0.01421875" iyz="0.0" izz="0.0234375"/>
    </inertial>
  </link>
  <gazebo reference="base_link">
    <material>Gazebo/White</material>
  </gazebo>
  <!-- LEFT WHEEL LINK -->
  <joint name="left_wheel_joint" type="continuous">
    <parent link="base_link"/>
    <child link="left_wheel_link"/>
    <origin rpy="0.0 0.0 0.0" xyz="0.0 0.08 0.0"/>
    <axis xyz="0.0 1.0 0.0"/>
  </joint>
  <link name="left_wheel_link">
    <visual>
      <origin rpy="1.5707 0.0 0.0"/>
      <geometry>
        <cylinder length="0.005" radius="0.053"/>
      </geometry>
      <material name="black"/>
    </visual>
    <collision>
      <origin rpy="1.5707 0.0 0.0"/>
      <geometry>
        <cylinder length="0.005" radius="0.053"/>
      </geometry>
    </collision>
    <inertial>
      <origin rpy="0.0 0.0 0.0" xyz="0.0 0.0 0.0"/>
      <mass value="0.01"/>
      <inertia ixx="7.043333333333334e-06" ixy="0.0" ixz="0.0" iyy="7.043333333333334e-06" iyz="0.0" izz="1.4045e-05"/>
    </inertial>
  </link>
  <gazebo reference="left_wheel_link">
    <material>Gazebo/Black</material>
    <mu1 value="1.0"/>
    <mu2 value="1.0"/>
  </gazebo>
  <!-- RIGHT WHEEL LINK -->
  <joint name="right_wheel_joint" type="continuous">
    <parent link="base_link"/>
    <child link="right_wheel_link"/>
    <origin rpy="0.0 0.0 0.0" xyz="0.0 -0.08 0.0"/>
    <axis xyz="0.0 1.0 0.0"/>
  </joint>
  <link name="right_wheel_link">
    <visual>
      <origin rpy="1.5707 0.0 0.0"/>
      <geometry>
        <cylinder length="0.005" radius="0.053"/>
      </geometry>
      <material name="black"/>
    </visual>
    <collision>
      <origin rpy="1.5707 0.0 0.0"/>
      <geometry>
        <cylinder length="0.005" radius="0.053"/>
      </geometry>
    </collision>
    <inertial>
      <origin rpy="0.0 0.0 0.0" xyz="0.0 0.0 0.0"/>
      <mass value="0.01"/>
      <inertia ixx="7.043333333333334e-06" ixy="0.0" ixz="0.0" iyy="7.043333333333334e-06" iyz="0.0" izz="1.4045e-05"/>
    </inertial>
  </link>
  <gazebo reference="right_wheel_link">
    <material>Gazebo/Black</material>
    <mu1 value="1.0"/>
    <mu2 value="1.0"/>
  </gazebo>
  <!-- FRONT CASTER LINK -->
  <joint name="front_caster_joint" type="fixed">
    <parent link="base_link"/>
    <child link="front_caster_link"/>
    <origin xyz="0.08 0.0 0.0"/>
  </joint>
  <link name="front_caster_link">
    <visual>
      <origin xyz="0.0 0.0 -0.01"/>
      <!--0.26-->
      <geometry>
        <cylinder length="0.052" radius="0.0125"/>
      </geometry>
      <material name="black"/>
    </visual>
    <collision>
      <origin xyz="0.0 0.0 -0.026"/>
      <geometry>
        <cylinder length="0.052" radius="0.0125"/>
      </geometry>
    </collision>
    <inertial>
      <origin rpy="0.0 0.0 0.0" xyz="0.0 0.0 -0.026"/>
      <mass value="0.01"/>
      <inertia ixx="2.643958333333333e-06" ixy="0.0" ixz="0.0" iyy="2.643958333333333e-06" iyz="0.0" izz="7.812500000000001e-07"/>
    </inertial>
  </link>
  <gazebo reference="front_caster_link">
    <material>Gazebo/Black</material>
    <mu1 value="0.001"/>
    <mu2 value="0.001"/>
  </gazebo>
  <!-- BACK CASTER LINK -->
  <joint name="back_caster_joint" type="fixed">
    <parent link="base_link"/>
    <child link="back_caster_link"/>
    <origin xyz="-0.08 0.0 0.0"/>
  </joint>
  <link name="back_caster_link">
    <visual>
      <origin xyz="0.0 0.0 -0.01"/>
      <!--0.26-->
      <geometry>
        <cylinder length="0.052" radius="0.025"/>
      </geometry>
      <material name="white"/>
    </visual>
    <collision>
      <origin xyz="0.0 0.0 -0.026"/>
      <geometry>
        <cylinder length="0.052" radius="0.025"/>
      </geometry>
    </collision>
    <inertial>
      <origin rpy="0.0 0.0 0.0" xyz="0.0 0.0 -0.026"/>
      <mass value="0.01"/>
      <inertia ixx="3.8158333333333325e-06" ixy="0.0" ixz="0.0" iyy="3.8158333333333325e-06" iyz="0.0" izz="3.1250000000000006e-06"/>
    </inertial>
  </link>
  <gazebo reference="back_caster_link">
    <material>Gazebo/White</material>
    <mu1 value="0.001"/>
    <mu2 value="0.001"/>
  </gazebo>
  <gazebo>
    <plugin filename="libgazebo_ros_diff_drive.so" name="diff_drive">
      <update_rate>50</update_rate>
      <!-- WEHEEL INFORMATION-->
      <left_joint>left_wheel_joint</left_joint>
      <right_joint>right_wheel_joint</right_joint>
      <wheel_separation>0.19</wheel_separation>
      <wheel_diameter>0.103</wheel_diameter>
      <!-- LIMITS -->
      <max_wheel_torque>500</max_wheel_torque>
      <max_wheel_acceleration>10</max_wheel_acceleration>
      <!-- velocity -->
      <max_velocity>2.0</max_velocity>
      <min_velocity>-2.0</min_velocity>
      <!-- OUTPUT -->
      <odometry_frame>odom</odometry_frame>
      <robot_base_frame>base_footprint_link</robot_base_frame>
      <publish_odom>true</publish_odom>
      <publish_odom_tf>true</publish_odom_tf>
      <publish_wheel_tf>true</publish_wheel_tf>
    </plugin>
  </gazebo>
  <material name="blue">
    <color rgba="0.2 0.2 1.0 1.0"/>
  </material>
  <joint name="laser_joint" type="fixed">
    <parent link="base_link"/>
    <child link="laser_frame"/>
    <origin rpy="0.0 0.0 0.0" xyz="-0.065 0.0 0.1367"/>
  </joint>
  <link name="laser_frame">
    <visual>
      <geometry>
        <cylinder length="0.025" radius="0.033"/>
      </geometry>
      <material name="blue"/>
    </visual>
    <collision>
      <geometry>
        <cylinder length="0.025" radius="0.033"/>
      </geometry>
    </collision>
    <inertial>
      <origin rpy="0.0 0.0 0.0" xyz="0.0 0.0 0.0"/>
      <mass value="0.1"/>
      <inertia ixx="3.243333333333334e-05" ixy="0.0" ixz="0.0" iyy="3.243333333333334e-05" iyz="0.0" izz="5.445000000000001e-05"/>
    </inertial>
  </link>
  <gazebo reference="laser_frame">
    <material>Gazebo/Blue</material>
    <sensor name="laser" type="ray">
      <pose> 0 0 0 0 0 0 </pose>
      <visualize>true</visualize>
      <update_rate>10</update_rate>
      <ray>
        <scan>
          <horizontal>
            <samples>360</samples>
            <min_angle>-3.14</min_angle>
            <max_angle>3.14</max_angle>
          </horizontal>
        </scan>
        <range>
          <min>0.3</min>
          <max>12</max>
        </range>
      </ray>
      <plugin filename="libgazebo_ros_ray_sensor.so" name="laser_controller">
        <ros>
          <argument>~/out:=scan</argument>
        </ros>
        <output_type>sensor_msgs/LaserScan</output_type>
        <frame_name>laser_frame</frame_name>
      </plugin>
    </sensor>
  </gazebo>
</robot>
